Workbook
Name DATA_START_ROW: CONFIG!$B$10
Name DATA_END_ROW: CONFIG!$B$11
Name NUM_PCS: CONFIG!$B$6
Name MATRIX_TYPE: CONFIG!$B$7
Name CONF_LEVEL: CONFIG!$B$8
Name INCLUDE_INT: CONFIG!$B$9

Sheet DATA
A1: PCA ANALYTICS · DATA INPUT
A2: Replace placeholder formulas with CIQ PRO =CIQ() functions. Keep headers in Row 4. Data starts Row 5. Add/remove factor columns freely.
A4: Date | B4: Dep Var Return | C4: Factor 1 | D4: Factor 2 | E4: Factor 3 | F4: Factor 4 | G4: Factor 5 | H4: Factor 6 | I4: Factor 7 | J4: Factor 8 | K4: Factor 9 | L4: Factor 10 | N4: CIQ PRO Formula Reference
A5: =IFERROR(DATE(2020,1,1),"") | N5: Single value: | O5: =CIQ("TICKER","IQ_TOTAL_RETURN","IQ_FY0")
A6: =A5+7 | N6: Time series: | O6: =CIQRANGE("TICKER","IQ_TOTAL_RETURN",start,end,"IQ_MONTHLY")
A7: =A6+7 | N7: Index return: | O7: =CIQ("SP500","IQ_TOTAL_RETURN","IQ_FY-1")
A8: =A7+7 | N8: Tip: | O8: Paste Transpose for vertical time series
A9: =A8+7
A10: =A9+7
A11: =A10+7
A12: =A11+7
A13: =A12+7
A14: =A13+7
A15: =A14+7
A16: =A15+7
A17: =A16+7
A18: =A17+7
A19: =A18+7
A20: =A19+7
... A54: =A53+7

Sheet CONFIG
A1: CONFIGURATION & LABELS
A3: A. ANALYSIS SETTINGS
A4: Dependent Variable Name | B4: Portfolio Return | C4: Displayed in all outputs
A5: Number of Factors (auto) | B5: =COUNTA(DATA!B4:K4)-1 | C5: Auto-counted — do not edit
A6: PCs to Retain | B6: 5 | C6: PCs shown in output / charts
A7: Matrix Type | B7: Correlation | C7: Correlation or Covariance
A8: Confidence Level | B8: 0.95 | C8: For regression CIs (e.g. 0.95)
A9: Include Intercept | B9: Yes | C9: Yes / No
A10: Data Start Row (DATA) | B10: 5 | C10: First data row on DATA sheet
A11: Data End Row (DATA) | B11: =COUNTA(DATA!A:A)+3 | C11: Last data row (auto)
A13: B. FACTOR LABELS (auto-populated from DATA Row 4 — edit Display Name)
A14: Factor # | B14: DATA Header (auto) | C14: Display Name | D14: Color Tag
A15: Factor 1 | B15: =IFERROR(DATA!C$4,"") | C15: =B15
A16: Factor 2 | B16: =IFERROR(DATA!D$4,"") | C16: =B16
A17: Factor 3 | B17: =IFERROR(DATA!E$4,"") | C17: =B17
A18: Factor 4 | B18: =IFERROR(DATA!F$4,"") | C18: =B18
A19: Factor 5 | B19: =IFERROR(DATA!G$4,"") | C19: =B19
A20: Factor 6 | B20: =IFERROR(DATA!H$4,"") | C20: =B20
A21: Factor 7 | B21: =IFERROR(DATA!I$4,"") | C21: =B21
A22: Factor 8 | B22: =IFERROR(DATA!J$4,"") | C22: =B22
A23: Factor 9 | B23: =IFERROR(DATA!K$4,"") | C23: =B23
A24: Factor 10 | B24: =IFERROR(DATA!L$4,"") | C24: =B24
A26: C. PRINCIPAL COMPONENT LABELS (rename your PCs here)
A27: PC # | B27: Default Name | C27: Custom Label | D27: Economic Interpretation | E27: Include in PCA Reg?
A28: PC1 | B28: PC1 | C28: PC1 | E28: Yes
A29: PC2 | B29: PC2 | C29: PC2 | E29: Yes
A30: PC3 | B30: PC3 | C30: PC3 | E30: Yes
A31: PC4 | B31: PC4 | C31: PC4 | E31: Yes
A32: PC5 | B32: PC5 | C32: PC5 | E32: Yes
A33: PC6 | B33: PC6 | C33: PC6 | E33: No
A34: PC7 | B34: PC7 | C34: PC7 | E34: No
A35: PC8 | B35: PC8 | C35: PC8 | E35: No
A36: PC9 | B36: PC9 | C36: PC9 | E36: No
A37: PC10 | B37: PC10 | C37: PC10 | E37: No
A39: Yellow cells = user-editable

Sheet PCA
A1: PRINCIPAL COMPONENT ANALYSIS OUTPUT
A2: Click RUN PCA (button below) or press Ctrl+Shift+P to execute. All tables are populated by VBA — do not edit directly.
A4: 1. SUMMARY STATISTICS
A5: Factor | B5: N | C5: Mean | D5: Std Dev | E5: Min | F5: Max
A6: =IFERROR(CONFIG!C15,"")
A7: =IFERROR(CONFIG!C16,"")
A8: =IFERROR(CONFIG!C17,"")
A9: =IFERROR(CONFIG!C18,"")
A10: =IFERROR(CONFIG!C19,"")
A11: =IFERROR(CONFIG!C20,"")
A12: =IFERROR(CONFIG!C21,"")
A13: =IFERROR(CONFIG!C22,"")
A14: =IFERROR(CONFIG!C23,"")
A15: =IFERROR(CONFIG!C24,"")
A17: 2. CORRELATION / COVARIANCE MATRIX (set in CONFIG)
B18: F1 | C18: F2 | D18: F3 | E18: F4 | F18: F5 | G18: F6 | H18: F7 | I18: F8 | J18: F9 | K18: F10
A19: F1
A20: F2
A21: F3
A22: F4
A23: F5
A24: F6
A25: F7
A26: F8
A27: F9
A28: F10
A30: 3. EIGENVALUES & VARIANCE EXPLAINED
A31: PC | B31: Eigenvalue | C31: % Variance | D31: Cumulative % | E31: Status | F31: Label (CONFIG)
A32: =IFERROR(CONFIG!C28,"") | F32: =IFERROR(CONFIG!D28,"")
A33: =IFERROR(CONFIG!C29,"") | F33: =IFERROR(CONFIG!D29,"")
A34: =IFERROR(CONFIG!C30,"") | F34: =IFERROR(CONFIG!D30,"")
A35: =IFERROR(CONFIG!C31,"") | F35: =IFERROR(CONFIG!D31,"")
A36: =IFERROR(CONFIG!C32,"") | F36: =IFERROR(CONFIG!D32,"")
A37: =IFERROR(CONFIG!C33,"") | F37: =IFERROR(CONFIG!D33,"")
A38: =IFERROR(CONFIG!C34,"") | F38: =IFERROR(CONFIG!D34,"")
A39: =IFERROR(CONFIG!C35,"") | F39: =IFERROR(CONFIG!D35,"")
A40: =IFERROR(CONFIG!C36,"") | F40: =IFERROR(CONFIG!D36,"")
A41: =IFERROR(CONFIG!C37,"") | F41: =IFERROR(CONFIG!D37,"")
A43: 4. FACTOR LOADINGS (eigenvectors × √eigenvalue)
A44: Factor \ PC | B44: =IFERROR(CONFIG!C28,"PC1") | C44: =IFERROR(CONFIG!C29,"PC2") | D44: =IFERROR(CONFIG!C30,"PC3") | E44: =IFERROR(CONFIG!C31,"PC4") | F44: =IFERROR(CONFIG!C32,"PC5") | G44: =IFERROR(CONFIG!C33,"PC6") | H44: =IFERROR(CONFIG!C34,"PC7") | I44: =IFERROR(CONFIG!C35,"PC8") | J44: =IFERROR(CONFIG!C36,"PC9") | K44: =IFERROR(CONFIG!C37,"PC10")
...

Sheet REGRESSION
A1: OLS REGRESSION — Dependent Variable on Original Factors
A2: Click RUN REGRESSION or press Ctrl+Shift+R. All cells populated by VBA.
A4: 1. MODEL SUMMARY
A5: Dependent Variable
A6: N (Observations)
A7: R-Squared
A8: Adjusted R-Squared
A9: F-Statistic
A10: Prob (F-Stat)
A11: AIC
A12: BIC
A14: 2. ANOVA TABLE
A15: Source | B15: SS | C15: df | D15: MS | E15: F | F15: Prob(F)
A16: Regression
A17: Residual
A18: Total
A20: 3. COEFFICIENTS
A21: Variable | B21: Coefficient | C21: Std Error | D21: t-Stat | E21: p-Value | F21: CI Lower | G21: CI Upper | H21: Significance
A22: Intercept
A23: =IFERROR(CONFIG!C15,"")
A24: =IFERROR(CONFIG!C16,"")
A25: =IFERROR(CONFIG!C17,"")
A26: =IFERROR(CONFIG!C18,"")
A27: =IFERROR(CONFIG!C19,"")
A28: =IFERROR(CONFIG!C20,"")
A29: =IFERROR(CONFIG!C21,"")
A30: =IFERROR(CONFIG!C22,"")
A31: =IFERROR(CONFIG!C23,"")
A32: =IFERROR(CONFIG!C24,"")
A33: =IFERROR(CONFIG!C25,"")
A35: 4. RESIDUALS (populated by VBA)
A36: Date | B36: Actual | C36: Fitted | D36: Residual | E36: Std Residual

Sheet PCA_REG
A1: PCA REGRESSION — Dependent Variable on Principal Components
A2: Click RUN PCA REGRESSION or Ctrl+Shift+Q. PCs used are controlled by CONFIG Section C column E.
A4: 1. PC REGRESSION MODEL SUMMARY
A5: Dependent Variable
A6: PCs Included
A7: N
A8: R-Squared
A9: Adjusted R-Squared
A10: F-Statistic
A11: Prob (F-Stat)
A13: 2. PC COEFFICIENTS
A14: PC | B14: Label | C14: Coeff | D14: Std Error | E14: t-Stat | F14: p-Value | G14: CI Lower | H14: CI Upper
A15: Intercept
A16: PC1 | B16: =IFERROR(CONFIG!C28,"")
A17: PC2 | B17: =IFERROR(CONFIG!C29,"")
A18: PC3 | B18: =IFERROR(CONFIG!C30,"")
A19: PC4 | B19: =IFERROR(CONFIG!C31,"")
A20: PC5 | B20: =IFERROR(CONFIG!C32,"")
A21: PC6 | B21: =IFERROR(CONFIG!C33,"")
A22: PC7 | B22: =IFERROR(CONFIG!C34,"")
A23: PC8 | B23: =IFERROR(CONFIG!C35,"")
A24: PC9 | B24: =IFERROR(CONFIG!C36,"")
A25: PC10 | B25: =IFERROR(CONFIG!C37,"")
A27: 3. BACK-TRANSFORMED FACTOR CONTRIBUTIONS (via PC loadings)
A28: Factor | B28: Display Name | C28: PC Contribution | D28: % of R²
A29: Factor 1 | B29: =IFERROR(CONFIG!C15,"")
A30: Factor 2 | B30: =IFERROR(CONFIG!C16,"")
A31: Factor 3 | B31: =IFERROR(CONFIG!C17,"")
A32: Factor 4 | B32: =IFERROR(CONFIG!C18,"")
A33: Factor 5 | B33: =IFERROR(CONFIG!C19,"")
A34: Factor 6 | B34: =IFERROR(CONFIG!C20,"")
A35: Factor 7 | B35: =IFERROR(CONFIG!C21,"")
A36: Factor 8 | B36: =IFERROR(CONFIG!C22,"")
A37: Factor 9 | B37: =IFERROR(CONFIG!C23,"")
A38: Factor 10 | B38: =IFERROR(CONFIG!C24,"")

Sheet CHARTS
A1: CHARTS — Populated by RUN PCA / RUN REGRESSION
A2: Charts are created / refreshed automatically when you run the analysis. Scree plot | Cumulative Variance | Factor Loadings Heatmap | PC Scores | Residuals
A4: SCREE PLOT
A5: (chart auto-populated by VBA)
A26: CUMULATIVE VARIANCE EXPLAINED | I26: PC SCORES (Time Series)
A27: (chart auto-populated by VBA) | I27: (chart auto-populated by VBA)
A48: FACTOR LOADINGS HEATMAP
A49: (chart auto-populated by VBA)
